File: public/thermal_text.txt
#FILE:X_(10K-min)_30C_500C_04.10.2024.ngb-ds3
#FORMAT:NETZSCH5
#IDENTITY:1
#DECIMAL:POINT
#SEPARATOR:SEMICOLON
#MTYPE:DTA
#INSTRUMENT:NETZSCH STA 449F3
#PROJECT:ChR1
#DATE/TIME:21/03/2007 6:46:19
#CORR. FILE:Correction Empty_DTA_TG_Al2O3_(10K-min)_30C_1300C_03.10.2024_NEW CRUCIBLE.ngb-bs3
#LABORATORY:203
#OPERATOR:Askar
#REMARK:
#SAMPLE:1200
#SAMPLE MASS /mg:23.730
#MATERIAL:Pudre
#REFERENCE:empty
#REFERENCE MASS /mg:0
#TYPE OF CRUCIBLE:DTA/TG crucible Al2O3
#SAMPLE CRUCIBLE MASS /mg:0.0
#REFERENCE CRUCIBLE MASS /mg:0
#CORR. CODE:020
#EXO:-1
#RANGE:30/10.0(K/min)/500
#SEGMENT:S1/1

##Temp./°C;Time/min;DTA/(uV/mg);Mass/%;Sensit./(uV/mW)
 22.82100;0.0000e+000; 0.0000e+000;100.00000;1.00000
 22.82300;5.0000e-002; 6.4302e-005;100.40034;1.00000
 22.80900;1.0000e-001;-1.2860e-004;100.38348;1.00000
 22.82600;    0.15000;-1.6075e-004;100.37927;1.00000
 22.82900;    0.20000;-2.5721e-004;100.38348;1.00000
 22.84400;    0.25000;-6.4302e-004;100.38769;1.00000
 22.88500;    0.30000;-1.4468e-003;100.39191;1.00000
 22.94600;    0.35000;-2.1220e-003;100.40455;1.00000
 23.01800;    0.40000;-3.2151e-003;100.42562;1.00000
 23.16600;    0.45000;-4.5333e-003;100.44669;1.00000
 23.32200;    0.50000;-5.7872e-003;100.43826;1.00000
 23.52800;    0.55000;-7.0732e-003;100.44669;1.00000
 23.76000;    0.60000;-8.6807e-003;100.41298;1.00000
 23.99700;    0.65000;-9.9668e-003;100.47619;1.00000
 24.32300;    0.70000;-1.1092e-002;100.46355;1.00000
 24.64500;    0.75000;-1.1639e-002;100.49726;1.00000
 25.02500;    0.80000;-1.2732e-002;100.52255;1.00000
 25.42000;    0.85000;-1.3632e-002;100.54362;1.00000
 25.84500;    0.90000;-1.4146e-002;100.54362;1.00000
 26.30300;    0.95000;-1.5143e-002;100.54362;1.00000
 26.78700;    1.00000;-1.5047e-002;100.54783;1.00000
 27.26600;    1.05000;-1.5529e-002;100.54362;1.00000
 27.80300;    1.10000;-1.5657e-002;100.55626;1.00000
 28.34600;    1.15000;-1.5754e-002;100.57311;1.00000
 28.91900;    1.20000;-1.6043e-002;100.57733;1.00000
 29.49700;    1.25000;-1.5625e-002;100.57733;1.00000
 30.10000;    1.30000;-1.5754e-002;100.56890;1.00000
 30.71500;    1.35000;-1.5850e-002;100.57311;1.00000
 31.32800;    1.40000;-1.5561e-002;100.57733;1.00000
 31.98200;    1.45000;-1.5561e-002;100.58154;1.00000
 32.63900;    1.50000;-1.5175e-002;100.58997;1.00000
 33.32400;    1.55000;-1.4854e-002;100.58576;1.00000
 34.01900;    1.60000;-1.4532e-002;100.58576;1.00000
 34.70100;    1.65000;-1.4307e-002;100.58576;1.00000
 35.42700;    1.70000;-1.3857e-002;100.57733;1.00000
 36.14200;    1.75000;-1.3568e-002;100.58154;1.00000
 36.87000;    1.80000;-1.3600e-002;100.57733;1.00000
 37.60300;    1.85000;-1.2860e-002;100.58576;1.00000
 38.35600;    1.90000;-1.2700e-002;100.58576;1.00000
 39.11400;    1.95000;-1.1928e-002;100.58154;1.00000
 39.88700;    2.00000;-1.1832e-002;100.58576;1.00000
 40.64200;    2.05000;-1.1124e-002;100.58154;1.00000
 41.41400;    2.10000;-1.0803e-002;100.57733;1.00000
 42.20300;    2.15000;-1.0192e-002;100.56890;1.00000
 42.99000;    2.20000;-9.6774e-003;100.56890;1.00000
 43.78000;    2.25000;-9.2273e-003;100.56890;1.00000
 44.56900;    2.30000;-8.8093e-003;100.56890;1.00000
 45.36000;    2.35000;-8.2306e-003;100.56890;1.00000
 46.15100;    2.40000;-7.9091e-003;100.56469;1.00000
 46.95500;    2.45000;-7.2661e-003;100.55204;1.00000
 47.73800;    2.50000;-6.5588e-003;100.55204;1.00000
 48.54300;    2.55000;-6.2373e-003;100.53519;1.00000
 49.35200;    2.60000;-5.4656e-003;100.53519;1.00000
 50.13000;    2.65000;-4.7905e-003;100.53519;1.00000
 50.93600;    2.70000;-4.1796e-003;100.53097;1.00000
 51.72600;    2.75000;-3.6330e-003;100.52255;1.00000
 52.49400;    2.80000;-3.3758e-003;100.51833;1.00000
 53.28300;    2.85000;-2.9579e-003;100.51833;1.00000
 54.06500;    2.90000;-2.2506e-003;100.50990;1.00000
 54.84300;    2.95000;-1.7683e-003;100.50990;1.00000
 55.60100;    3.00000;-1.1253e-003;100.50569;1.00000
 56.36300;    3.05000;-5.1441e-004;100.50569;1.00000
 57.12700;    3.10000;-9.6452e-005;100.50147;1.00000
 57.88000;    3.15000; 4.8226e-004;100.49726;1.00000
 58.64600;    3.20000; 5.7871e-004;100.49305;1.00000
 59.40200;    3.25000; 1.1574e-003;100.48883;1.00000
 60.14600;    3.30000; 1.7361e-003;100.48462;1.00000
 60.86000;    3.35000; 2.1863e-003;100.48040;1.00000
 61.58600;    3.40000; 2.5721e-003;100.47619;1.00000
 62.30900;    3.45000; 3.2472e-003;100.47198;1.00000
 63.02900;    3.50000; 3.7295e-003;100.46355;1.00000
 63.73600;    3.55000; 3.8903e-003;100.45933;1.00000
 64.42900;    3.60000; 4.2118e-003;100.45512;1.00000
 65.12200;    3.65000; 4.4690e-003;100.45512;1.00000
 65.81500;    3.70000; 4.5333e-003;100.44669;1.00000
 66.50600;    3.75000; 4.7583e-003;100.44669;1.00000
 67.17800;    3.80000; 4.9834e-003;100.44248;1.00000
 67.83200;    3.85000; 5.4013e-003;100.44248;1.00000
 68.50700;    3.90000; 5.5299e-003;100.43405;1.00000
 69.15600;    3.95000; 5.4335e-003;100.43405;1.00000
 69.79700;    4.00000; 6.1408e-003;100.42562;1.00000
 70.43300;    4.05000; 6.1730e-003;100.42984;1.00000
 71.06800;    4.10000; 5.8836e-003;100.42141;1.00000
 71.70400;    4.15000; 6.0444e-003;100.41719;1.00000
 72.29600;    4.20000; 6.0444e-003;100.41719;1.00000
 72.93100;    4.25000; 5.7550e-003;100.41298;1.00000
 73.51999;    4.30000; 6.0765e-003;100.41719;1.00000
 74.12500;    4.35000; 5.8836e-003;100.41719;1.00000
 74.72500;    4.40000; 6.1408e-003;100.41298;1.00000
 75.30600;    4.45000; 5.6264e-003;100.40877;1.00000
 75.89800;    4.50000; 5.3049e-003;100.40455;1.00000
 76.46499;    4.55000; 5.3370e-003;100.40455;1.00000
 77.03900;    4.60000; 5.2727e-003;100.40455;1.00000
 77.60900;    4.65000; 5.0477e-003;100.40034;1.00000
 78.17800;    4.70000; 4.6619e-003;100.40455;1.00000
 78.70700;    4.75000; 4.7905e-003;100.39612;1.00000
 79.24800;    4.80000; 4.4047e-003;100.39612;1.00000
 79.79300;    4.85000; 4.5333e-003;100.38769;1.00000
 80.33500;    4.90000; 4.0832e-003;100.38348;1.00000
 80.87800;    4.95000; 3.8581e-003;100.38348;1.00000
 81.40600;    5.00000; 3.9224e-003;100.37927;1.00000
 81.94000;    5.05000; 3.4080e-003;100.37505;1.00000
 82.44400;    5.10000; 3.2794e-003;100.37927;1.00000
 82.97200;    5.15000; 2.9257e-003;100.38348;1.00000
 83.49100;    5.20000; 2.3792e-003;100.37927;1.00000
 83.98100;    5.25000; 2.3470e-003;100.37505;1.00000
 84.50200;    5.30000; 1.8004e-003;100.37505;1.00000
 84.98700;    5.35000; 1.3503e-003;100.37084;1.00000
 85.50100;    5.40000; 1.2860e-003;100.36662;1.00000
 85.99900;    5.45000; 8.0377e-004;100.37505;1.00000
 86.49300;    5.50000; 3.8581e-004;100.36662;1.00000
 86.97899;    5.55000; 6.4304e-005;100.36662;1.00000
 87.47100;    5.60000;-2.8936e-004;100.35820;1.00000
 87.95900;    5.65000;-6.4302e-004;100.35398;1.00000
 88.43100;    5.70000;-9.6452e-004;100.34977;1.00000
 88.91400;    5.75000;-1.4468e-003;100.34977;1.00000
 89.40300;    5.80000;-2.0898e-003;100.35398;1.00000
 89.86500;    5.85000;-2.6364e-003;100.34977;1.00000
 90.34100;    5.90000;-2.9900e-003;100.34977;1.00000
 90.80800;    5.95000;-3.0865e-003;100.34555;1.00000
 91.27900;    6.00000;-3.5044e-003;100.34555;1.00000
 91.74600;    6.05000;-4.1153e-003;100.34134;1.00000
 92.21800;    6.10000;-4.4368e-003;100.34134;1.00000
 92.66700;    6.15000;-4.8226e-003;100.34134;1.00000
 93.13301;    6.20000;-5.2727e-003;100.33713;1.00000
 93.60300;    6.25000;-6.0765e-003;100.33291;1.00000
 94.06199;    6.30000;-6.3659e-003;100.33291;1.00000
 94.52400;    6.35000;-6.5909e-003;100.32870;1.00000
 94.98900;    6.40000;-7.1053e-003;100.32448;1.00000
 95.44100;    6.45000;-7.2661e-003;100.32448;1.00000
 95.90900;    6.50000;-7.8770e-003;100.32448;1.00000
 96.36900;    6.55000;-8.2628e-003;100.32448;1.00000
 96.83200;    6.60000;-8.8093e-003;100.32448;1.00000
 97.29400;    6.65000;-9.1308e-003;100.32027;1.00000
 97.72200;    6.70000;-9.7417e-003;100.32027;1.00000
 98.19000;    6.75000;-9.9025e-003;100.32027;1.00000
 98.65400;    6.80000;-1.0353e-002;100.32027;1.00000
 99.10600;    6.85000;-1.0674e-002;100.31606;1.00000
 99.56900;    6.90000;-1.1317e-002;100.31606;1.00000
100.01700;    6.95000;-1.1799e-002;100.31606;1.00000
100.48300;    7.00000;-1.2249e-002;100.31606;1.00000
100.93699;    7.05000;-1.2185e-002;100.31606;1.00000
101.39900;    7.10000;-1.2571e-002;100.31606;1.00000
101.85000;    7.15000;-1.3214e-002;100.30763;1.00000
102.31400;    7.20000;-1.3407e-002;100.30763;1.00000
102.76400;    7.25000;-1.3761e-002;100.30763;1.00000
103.22899;    7.30000;-1.4275e-002;100.30763;1.00000
103.69800;    7.35000;-1.4629e-002;100.29920;1.00000
104.15400;    7.40000;-1.5047e-002;100.29920;1.00000
104.60300;    7.45000;-1.5336e-002;100.29920;1.00000
105.07000;    7.50000;-1.5754e-002;100.29920;1.00000
105.52300;    7.55000;-1.6429e-002;100.29920;1.00000
105.99000;    7.60000;-1.6686e-002;100.29077;1.00000
106.45600;    7.65000;-1.6718e-002;100.29077;1.00000
106.92200;    7.70000;-1.7233e-002;100.29077;1.00000
107.39200;    7.75000;-1.7426e-002;100.28234;1.00000
107.85100;    7.80000;-1.7747e-002;100.28234;1.00000
108.31000;    7.85000;-1.8230e-002;100.27391;1.00000
108.78400;    7.90000;-1.8680e-002;100.27391;1.00000
109.25500;    7.95000;-1.8680e-002;100.27391;1.00000
109.71400;    8.00000;-1.9130e-002;100.27391;1.00000
110.19500;    8.05000;-1.9323e-002;100.27391;1.00000
110.67299;    8.10000;-1.9773e-002;100.26549;1.00000
111.14901;    8.15000;-2.0255e-002;100.26549;1.00000
111.59900;    8.20000;-2.0416e-002;100.26549;1.00000
112.08600;    8.25000;-2.0802e-002;100.26127;1.00000
112.56700;    8.30000;-2.0962e-002;100.26127;1.00000
113.04200;    8.35000;-2.1284e-002;100.25706;1.00000
113.50901;    8.40000;-2.1573e-002;100.25284;1.00000
113.98900;    8.45000;-2.1830e-002;100.24863;1.00000
114.48700;    8.50000;-2.2345e-002;100.24863;1.00000
114.94800;    8.55000;-2.2570e-002;100.24442;1.00000
115.43599;    8.60000;-2.2634e-002;100.24442;1.00000
115.92601;    8.65000;-2.2924e-002;100.24020;1.00000
116.41101;    8.70000;-2.3084e-002;100.23599;1.00000
116.89500;    8.75000;-2.3567e-002;100.24020;1.00000
117.37900;    8.80000;-2.3567e-002;100.23599;1.00000
117.86799;    8.85000;-2.3792e-002;100.23599;1.00000
118.34501;    8.90000;-2.3888e-002;100.23177;1.00000
118.84200;    8.95000;-2.4017e-002;100.23177;1.00000
119.33200;    9.00000;-2.4724e-002;100.22335;1.00000
119.82200;    9.05000;-2.4724e-002;100.22335;1.00000
120.32299;    9.10000;-2.5078e-002;100.22335;1.00000
120.80101;    9.15000;-2.5174e-002;100.21492;1.00000
121.32600;    9.20000;-2.5367e-002;100.21492;1.00000
121.80200;    9.25000;-2.5431e-002;100.21492;1.00000
122.30000;    9.30000;-2.5689e-002;100.21492;1.00000
122.79100;    9.35000;-2.6074e-002;100.20649;1.00000
123.29100;    9.40000;-2.6171e-002;100.20649;1.00000
123.79200;    9.45000;-2.6396e-002;100.20649;1.00000
124.29700;    9.50000;-2.6557e-002;100.20649;1.00000
124.79799;    9.55000;-2.7039e-002;100.19806;1.00000
125.29499;    9.60000;-2.7200e-002;100.19806;1.00000
125.79901;    9.65000;-2.7618e-002;100.19806;1.00000
126.30500;    9.70000;-2.8132e-002;100.19806;1.00000
126.82000;    9.75000;-2.8003e-002;100.19806;1.00000
127.31000;    9.80000;-2.8775e-002;100.18963;1.00000
127.81500;    9.85000;-2.9225e-002;100.18963;1.00000
128.32500;    9.90000;-2.9322e-002;100.18963;1.00000
128.81799;    9.95000;-2.9804e-002;100.18121;1.00000
129.33299;   10.00000;-3.0157e-002;100.17699;1.00000
129.83500;   10.05000;-3.0125e-002;100.17699;1.00000
130.34399;   10.10000;-3.0254e-002;100.17699;1.00000
130.84200;   10.15000;-3.0350e-002;100.17699;1.00000
131.35201;   10.20000;-3.0736e-002;100.17699;1.00000
131.85400;   10.25000;-3.1122e-002;100.17699;1.00000
132.37800;   10.30000;-3.1218e-002;100.17278;1.00000
132.88900;   10.35000;-3.1251e-002;100.16856;1.00000
133.38100;   10.40000;-3.1701e-002;100.16435;1.00000
133.89701;   10.45000;-3.1990e-002;100.16435;1.00000
134.41200;   10.50000;-3.1894e-002;100.16013;1.00000
134.91299;   10.55000;-3.2408e-002;100.15592;1.00000
135.42100;   10.60000;-3.2665e-002;100.15171;1.00000
135.93300;   10.65000;-3.2858e-002;100.15171;1.00000
136.44000;   10.70000;-3.2922e-002;100.14328;1.00000
136.96100;   10.75000;-3.3148e-002;100.14328;1.00000
137.46800;   10.80000;-3.3308e-002;100.14328;1.00000
137.98300;   10.85000;-3.3533e-002;100.14328;1.00000
138.48900;   10.90000;-3.3694e-002;100.13906;1.00000
138.99100;   10.95000;-3.4209e-002;100.13906;1.00000
139.51199;   11.00000;-3.3887e-002;100.13064;1.00000
140.01600;   11.05000;-3.4562e-002;100.13064;1.00000
140.54499;   11.10000;-3.4562e-002;100.12642;1.00000
141.05001;   11.15000;-3.4562e-002;100.12221;1.00000
141.56200;   11.20000;-3.5077e-002;100.12221;1.00000
142.06900;   11.25000;-3.5109e-002;100.11799;1.00000
142.59300;   11.30000;-3.5495e-002;100.11378;1.00000
143.09599;   11.35000;-3.5687e-002;100.11378;1.00000
143.60900;   11.40000;-3.5752e-002;100.11378;1.00000
144.10500;   11.45000;-3.6041e-002;100.09692;1.00000
144.63699;   11.50000;-3.6298e-002;100.09692;1.00000
145.14100;   11.55000;-3.6073e-002;100.09692;1.00000
145.64100;   11.60000;-3.6459e-002;100.09692;1.00000
146.15500;   11.65000;-3.6652e-002;100.08007;1.00000
146.65801;   11.70000;-3.6748e-002;100.08007;1.00000
147.16800;   11.75000;-3.7166e-002;100.08007;1.00000
147.67999;   11.80000;-3.7295e-002;100.07164;1.00000
148.19700;   11.85000;-3.7038e-002;100.07164;1.00000
148.69800;   11.90000;-3.7424e-002;100.07164;1.00000
149.21300;   11.95000;-3.7552e-002;100.06321;1.00000
149.70799;   12.00000;-3.8292e-002;100.07164;1.00000
150.21200;   12.05000;-3.8324e-002; 99.86515;1.00000
150.71000;   12.10000;-3.8710e-002; 99.93679;1.00000
151.22800;   12.15000;-3.8935e-002; 99.98314;1.00000
151.73500;   12.20000;-3.9128e-002; 99.99579;1.00000
152.23700;   12.25000;-3.9288e-002;100.00000;1.00000
152.73500;   12.30000;-3.9674e-002;100.00000;1.00000
153.22900;   12.35000;-3.9706e-002; 99.99579;1.00000
153.74300;   12.40000;-4.0092e-002;100.00000;1.00000
154.25800;   12.45000;-4.0574e-002; 99.99579;1.00000
154.75101;   12.50000;-4.0414e-002; 99.99157;1.00000
155.25900;   12.55000;-4.0703e-002; 99.99579;1.00000
155.75799;   12.60000;-4.0896e-002; 99.99157;1.00000
156.26000;   12.65000;-4.1185e-002; 99.98314;1.00000
156.75600;   12.70000;-4.1764e-002; 99.97893;1.00000
157.27000;   12.75000;-4.1764e-002; 99.97472;1.00000
157.76401;   12.80000;-4.2343e-002; 99.97472;1.00000
158.26699;   12.85000;-4.2793e-002; 99.97050;1.00000
158.76801;   12.90000;-4.2889e-002; 99.96207;1.00000
159.26200;   12.95000;-4.3211e-002; 99.95365;1.00000
159.77200;   13.00000;-4.3275e-002; 99.94100;1.00000
160.26800;   13.05000;-4.3854e-002; 99.94100;1.00000
160.77000;   13.10000;-4.4079e-002; 99.94100;1.00000
161.26900;   13.15000;-4.4272e-002; 99.93679;1.00000
161.76500;   13.20000;-4.4786e-002; 99.93679;1.00000
162.26601;   13.25000;-4.5301e-002; 99.92836;1.00000
162.77299;   13.30000;-4.5686e-002; 99.92415;1.00000
163.27499;   13.35000;-4.5590e-002; 99.92415;1.00000
163.77100;   13.40000;-4.5783e-002; 99.91150;1.00000
164.26401;   13.45000;-4.6201e-002; 99.90729;1.00000
164.76300;   13.50000;-4.6458e-002; 99.89886;1.00000
165.27099;   13.55000;-4.6683e-002; 99.89886;1.00000
165.76899;   13.60000;-4.6715e-002; 99.89465;1.00000
166.26700;   13.65000;-4.7551e-002; 99.89043;1.00000
166.76100;   13.70000;-4.7326e-002; 99.88622;1.00000
167.24600;   13.75000;-4.7423e-002; 99.88622;1.00000
167.75900;   13.80000;-4.7648e-002; 99.87779;1.00000
168.26600;   13.85000;-4.8001e-002; 99.87358;1.00000
168.75000;   13.90000;-4.8130e-002; 99.87358;1.00000
169.24700;   13.95000;-4.8451e-002; 99.86515;1.00000
169.75101;   14.00000;-4.8516e-002; 99.86094;1.00000
170.24299;   14.05000;-4.8387e-002; 99.85672;1.00000
170.73700;   14.10000;-4.8837e-002; 99.85251;1.00000
171.23301;   14.15000;-4.9062e-002; 99.84829;1.00000
171.73500;   14.20000;-4.9352e-002; 99.84408;1.00000
172.23700;   14.25000;-4.9287e-002; 99.83565;1.00000
172.74200;   14.30000;-4.9480e-002; 99.82722;1.00000
173.23899;   14.35000;-4.9802e-002; 99.82722;1.00000
173.71601;   14.40000;-5.0220e-002; 99.82722;1.00000
174.21601;   14.45000;-5.0509e-002; 99.81458;1.00000
174.72000;   14.50000;-5.0605e-002; 99.80194;1.00000
175.22400;   14.55000;-5.0927e-002; 99.79351;1.00000
175.72799;   14.60000;-5.1409e-002; 99.79351;1.00000
176.21401;   14.65000;-5.1666e-002; 99.78508;1.00000
176.73100;   14.70000;-5.1763e-002; 99.78508;1.00000
177.22000;   14.75000;-5.1988e-002; 99.77665;1.00000
177.71200;   14.80000;-5.2245e-002; 99.76823;1.00000
178.21699;   14.85000;-5.2052e-002; 99.76823;1.00000
178.71100;   14.90000;-5.2213e-002; 99.75980;1.00000
179.21800;   14.95000;-5.1924e-002; 99.74294;1.00000
179.71800;   15.00000;-5.2181e-002; 99.73873;1.00000
180.22301;   15.05000;-5.2245e-002; 99.73873;1.00000
180.71699;   15.10000;-5.1956e-002; 99.73451;1.00000
181.23101;   15.15000;-5.2342e-002; 99.73030;1.00000
181.71401;   15.20000;-5.2374e-002; 99.72609;1.00000
182.21899;   15.25000;-5.2695e-002; 99.72609;1.00000
182.72700;   15.30000;-5.2631e-002; 99.72609;1.00000
183.22200;   15.35000;-5.3338e-002; 99.71344;1.00000
183.72100;   15.40000;-5.3370e-002; 99.70923;1.00000
184.21900;   15.45000;-5.3724e-002; 99.70501;1.00000
184.71500;   15.50000;-5.4013e-002; 99.70080;1.00000
185.21100;   15.55000;-5.4335e-002; 99.69237;1.00000
185.72099;   15.60000;-5.4817e-002; 99.69237;1.00000
186.22301;   15.65000;-5.5492e-002; 99.69237;1.00000
186.72000;   15.70000;-5.5878e-002; 99.67552;1.00000
187.21201;   15.75000;-5.6296e-002; 99.67552;1.00000
187.72500;   15.80000;-5.6650e-002; 99.66709;1.00000
188.22300;   15.85000;-5.7196e-002; 99.66709;1.00000
188.72001;   15.90000;-5.7550e-002; 99.65866;1.00000
189.22100;   15.95000;-5.7872e-002; 99.65023;1.00000
189.73000;   16.00000;-5.8611e-002; 99.64180;1.00000
190.22201;   16.05000;-5.8611e-002; 99.63759;1.00000
190.72900;   16.10000;-5.9222e-002; 99.62495;1.00000
191.22701;   16.15000;-5.9833e-002; 99.62073;1.00000
191.73100;   16.20000;-6.0154e-002; 99.61652;1.00000
192.22800;   16.25000;-6.0669e-002; 99.61231;1.00000
192.72901;   16.30000;-6.1472e-002; 99.60809;1.00000
193.22400;   16.35000;-6.1762e-002; 99.59966;1.00000
193.73500;   16.40000;-6.2051e-002; 99.59123;1.00000
194.23100;   16.45000;-6.2501e-002; 99.59123;1.00000
194.72400;   16.50000;-6.3080e-002; 99.57859;1.00000
195.22401;   16.55000;-6.3498e-002; 99.57859;1.00000
195.73100;   16.60000;-6.3755e-002; 99.57438;1.00000
196.23600;   16.65000;-6.3787e-002; 99.56595;1.00000
196.73598;   16.70000;-6.4430e-002; 99.56174;1.00000
197.23199;   16.75000;-6.4913e-002; 99.55331;1.00000
197.72701;   16.80000;-6.5652e-002; 99.54909;1.00000
198.23199;   16.85000;-6.6102e-002; 99.54488;1.00000
198.73400;   16.90000;-6.6456e-002; 99.54067;1.00000
199.22900;   16.95000;-6.7067e-002; 99.53224;1.00000
199.72900;   17.00000;-6.7356e-002; 99.52802;1.00000
200.24900;   17.05000;-6.7742e-002; 99.52381;1.00000
200.73700;   17.10000;-6.8513e-002; 99.51538;1.00000
201.23700;   17.15000;-6.8578e-002; 99.51117;1.00000
201.73598;   17.20000;-6.9189e-002; 99.50695;1.00000
202.23300;   17.25000;-6.9639e-002; 99.49010;1.00000
202.72901;   17.30000;-6.9960e-002; 99.49010;1.00000
203.22999;   17.35000;-7.0475e-002; 99.48167;1.00000
203.74401;   17.40000;-7.0860e-002; 99.48167;1.00000
204.24299;   17.45000;-7.1246e-002; 99.47324;1.00000
204.72800;   17.50000;-7.1761e-002; 99.46481;1.00000
205.22601;   17.55000;-7.2179e-002; 99.46060;1.00000
205.72300;   17.60000;-7.2468e-002; 99.45217;1.00000
206.22501;   17.65000;-7.2564e-002; 99.44796;1.00000
206.73099;   17.70000;-7.3111e-002; 99.43953;1.00000
207.23199;   17.75000;-7.3497e-002; 99.43531;1.00000
207.72100;   17.80000;-7.3561e-002; 99.43531;1.00000
208.23700;   17.85000;-7.3947e-002; 99.42689;1.00000
208.72901;   17.90000;-7.4108e-002; 99.42267;1.00000
209.23499;   17.95000;-7.4461e-002; 99.41846;1.00000
209.72800;   18.00000;-7.4751e-002; 99.40582;1.00000
210.24300;   18.05000;-7.4783e-002; 99.40581;1.00000
210.75100;   18.10000;-7.5426e-002; 99.38896;1.00000
211.23700;   18.15000;-7.5426e-002; 99.38053;1.00000
211.72799;   18.20000;-7.5747e-002; 99.38053;1.00000
212.24400;   18.25000;-7.6133e-002; 99.38053;1.00000
212.74300;   18.30000;-7.5940e-002; 99.37210;1.00000
213.23199;   18.35000;-7.6390e-002; 99.36367;1.00000
213.72001;   18.40000;-7.6326e-002; 99.35103;1.00000
214.23499;   18.45000;-7.6455e-002; 99.34682;1.00000
214.72501;   18.50000;-7.6680e-002; 99.34260;1.00000
215.22600;   18.55000;-7.6808e-002; 99.33839;1.00000
215.73700;   18.60000;-7.7162e-002; 99.33418;1.00000
216.24300;   18.65000;-7.7323e-002; 99.32996;1.00000
216.71600;   18.70000;-7.7226e-002; 99.32575;1.00000
217.23100;   18.75000;-7.6873e-002; 99.31311;1.00000
217.71401;   18.80000;-7.7516e-002; 99.30889;1.00000
218.21699;   18.85000;-7.7484e-002; 99.30468;1.00000
218.72000;   18.90000;-7.7226e-002; 99.29625;1.00000
219.21699;   18.95000;-7.7741e-002; 99.29625;1.00000
219.70200;   19.00000;-7.7709e-002; 99.28782;1.00000
220.22201;   19.05000;-7.7323e-002; 99.28782;1.00000
220.71099;   19.10000;-7.7612e-002; 99.27939;1.00000
221.21700;   19.15000;-7.7516e-002; 99.27939;1.00000
221.72399;   19.20000;-7.7451e-002; 99.25832;1.00000
222.21600;   19.25000;-7.7676e-002; 99.25411;1.00000
222.72201;   19.30000;-7.7644e-002; 99.24989;1.00000
223.20799;   19.35000;-7.8094e-002; 99.24989;1.00000
223.71900;   19.40000;-7.7805e-002; 99.24568;1.00000
224.21000;   19.45000;-7.7419e-002; 99.24147;1.00000
224.71700;   19.50000;-7.7484e-002; 99.22461;1.00000
225.21101;   19.55000;-7.7484e-002; 99.22040;1.00000
225.72000;   19.60000;-7.7066e-002; 99.22040;1.00000
226.21500;   19.65000;-7.7098e-002; 99.21618;1.00000
226.71400;   19.70000;-7.7066e-002; 99.21197;1.00000
227.21201;   19.75000;-7.7066e-002; 99.20775;1.00000
227.70901;   19.80000;-7.7001e-002; 99.19933;1.00000
228.21899;   19.85000;-7.6712e-002; 99.19933;1.00000
228.72901;   19.90000;-7.6583e-002; 99.18247;1.00000
229.21099;   19.95000;-7.6198e-002; 99.18247;1.00000
229.71700;   20.00000;-7.6101e-002; 99.17404;1.00000
230.22201;   20.05000;-7.6326e-002; 99.17404;1.00000
230.71600;   20.10000;-7.5747e-002; 99.16140;1.00000
231.19901;   20.15000;-7.5490e-002; 99.15719;1.00000
231.71299;   20.20000;-7.5329e-002; 99.15297;1.00000
232.22501;   20.25000;-7.5265e-002; 99.14876;1.00000
232.71801;   20.30000;-7.4976e-002; 99.13611;1.00000
233.21600;   20.35000;-7.4783e-002; 99.13190;1.00000
233.71801;   20.40000;-7.4365e-002; 99.12769;1.00000
234.20499;   20.45000;-7.4076e-002; 99.12769;1.00000
234.72099;   20.50000;-7.3497e-002; 99.11926;1.00000
235.20200;   20.55000;-7.3336e-002; 99.11083;1.00000
235.69600;   20.60000;-7.2918e-002; 99.10662;1.00000
236.19901;   20.65000;-7.2468e-002; 99.09397;1.00000
236.70899;   20.70000;-7.1889e-002; 99.08976;1.00000
237.19800;   20.75000;-7.1600e-002; 99.08976;1.00000
237.69701;   20.80000;-7.1214e-002; 99.08133;1.00000
238.18800;   20.85000;-7.0250e-002; 99.07712;1.00000
238.68500;   20.90000;-7.0185e-002; 99.06869;1.00000
239.18699;   20.95000;-6.9382e-002; 99.06869;1.00000
239.69099;   21.00000;-6.8674e-002; 99.06026;1.00000
240.19501;   21.05000;-6.8128e-002; 99.05605;1.00000
240.69400;   21.10000;-6.7227e-002; 99.05183;1.00000
241.18201;   21.15000;-6.6649e-002; 99.04762;1.00000
241.67699;   21.20000;-6.5813e-002; 99.04762;1.00000
242.17400;   21.25000;-6.4945e-002; 99.04340;1.00000
242.67800;   21.30000;-6.3916e-002; 99.03498;1.00000
243.17500;   21.35000;-6.3080e-002; 99.03498;1.00000
243.67301;   21.40000;-6.2051e-002; 99.02655;1.00000
244.18899;   21.45000;-6.0862e-002; 99.02233;1.00000
244.68201;   21.50000;-5.9704e-002; 99.02233;1.00000
245.17400;   21.55000;-5.8740e-002; 99.01812;1.00000
245.68899;   21.60000;-5.7196e-002; 99.00969;1.00000
246.18900;   21.65000;-5.5782e-002; 99.00548;1.00000
246.67998;   21.70000;-5.4399e-002; 98.99705;1.00000
247.17999;   21.75000;-5.3210e-002; 98.98862;1.00000
247.69100;   21.80000;-5.1248e-002; 98.98862;1.00000
248.18800;   21.85000;-4.9898e-002; 98.98019;1.00000
248.68900;   21.90000;-4.8226e-002; 98.98019;1.00000
249.19999;   21.95000;-4.6233e-002; 98.98019;1.00000
249.69701;   22.00000;-4.5204e-002; 98.96334;1.00000
250.20400;   22.05000;-4.3597e-002; 98.96334;1.00000
250.69000;   22.10000;-4.2889e-002; 98.96334;1.00000
251.19001;   22.15000;-4.2343e-002; 98.96334;1.00000
251.68899;   22.20000;-4.2246e-002; 98.95491;1.00000
252.19099;   22.25000;-4.2439e-002; 98.95491;1.00000
252.69601;   22.30000;-4.3468e-002; 98.95491;1.00000
253.19400;   22.35000;-4.4658e-002; 98.95491;1.00000
253.69200;   22.40000;-4.6104e-002; 98.94648;1.00000
254.19799;   22.45000;-4.7648e-002; 98.94648;1.00000
254.70399;   22.50000;-5.0059e-002; 98.94648;1.00000
255.20600;   22.55000;-5.1570e-002; 98.94648;1.00000
255.70399;   22.60000;-5.3853e-002; 98.92962;1.00000
256.20902;   22.65000;-5.5653e-002; 98.92962;1.00000
256.70498;   22.70000;-5.8032e-002; 98.92120;1.00000
257.20099;   22.75000;-5.9897e-002; 98.91698;1.00000
257.71101;   22.80000;-6.2051e-002; 98.91698;1.00000
258.21701;   22.85000;-6.4044e-002; 98.91277;1.00000
258.70401;   22.90000;-6.6038e-002; 98.90855;1.00000
259.20998;   22.95000;-6.8095e-002; 98.90434;1.00000
259.70801;   23.00000;-7.0121e-002; 98.90434;1.00000
260.21900;   23.05000;-7.1632e-002; 98.90013;1.00000
260.71701;   23.10000;-7.3465e-002; 98.88748;1.00000
261.20600;   23.15000;-7.5169e-002; 98.88327;1.00000
261.71798;   23.20000;-7.6841e-002; 98.87906;1.00000
262.20599;   23.25000;-7.8866e-002; 98.87906;1.00000
262.71101;   23.30000;-8.0184e-002; 98.87484;1.00000
263.21600;   23.35000;-8.1535e-002; 98.87484;1.00000
263.71100;   23.40000;-8.2917e-002; 98.86641;1.00000
264.21398;   23.45000;-8.4525e-002; 98.86220;1.00000
264.72800;   23.50000;-8.5714e-002; 98.86220;1.00000
265.22102;   23.55000;-8.7225e-002; 98.85799;1.00000
265.72799;   23.60000;-8.8190e-002; 98.84956;1.00000
266.22199;   23.65000;-8.9412e-002; 98.84956;1.00000
266.71398;   23.70000;-9.0633e-002; 98.84113;1.00000
267.22900;   23.75000;-9.1887e-002; 98.84113;1.00000
267.72300;   23.80000;-9.2755e-002; 98.84113;1.00000
268.21701;   23.85000;-9.3752e-002; 98.83270;1.00000
268.72800;   23.90000;-9.4620e-002; 98.83270;1.00000
269.23199;   23.95000;-9.5681e-002; 98.82427;1.00000
269.72501;   24.00000;-9.6549e-002; 98.82427;1.00000
270.21800;   24.05000;-9.7224e-002; 98.82427;1.00000
270.73400;   24.10000;-9.8253e-002; 98.82427;1.00000
271.23700;   24.15000;-9.9057e-002; 98.81585;1.00000
271.72198;   24.20000;-9.9957e-002; 98.81584;1.00000
272.24301;   24.25000;    -0.10050; 98.81584;1.00000
272.73701;   24.30000;    -0.10118; 98.81584;1.00000
273.23999;   24.35000;    -0.10166; 98.79899;1.00000
273.72901;   24.40000;    -0.10263; 98.79477;1.00000
274.23598;   24.45000;    -0.10324; 98.79477;1.00000
274.73901;   24.50000;    -0.10388; 98.79477;1.00000
275.23402;   24.55000;    -0.10472; 98.79477;1.00000
275.73700;   24.60000;    -0.10539; 98.78635;1.00000
276.24100;   24.65000;    -0.10587; 98.77792;1.00000
276.74300;   24.70000;    -0.10655; 98.77792;1.00000
277.24701;   24.75000;    -0.10716; 98.76949;1.00000
277.74601;   24.80000;    -0.10774; 98.76949;1.00000
278.24099;   24.85000;    -0.10822; 98.76528;1.00000
278.73902;   24.90000;    -0.10844; 98.76106;1.00000
279.23299;   24.95000;    -0.10922; 98.75685;1.00000
279.72800;   25.00000;    -0.10992; 98.75263;1.00000
280.23701;   25.05000;    -0.11028; 98.74842;1.00000
280.73199;   25.10000;    -0.11092; 98.74421;1.00000
281.23401;   25.15000;    -0.11137; 98.73999;1.00000
281.74200;   25.20000;    -0.11198; 98.73156;1.00000
282.23199;   25.25000;    -0.11259; 98.72735;1.00000
282.72901;   25.30000;    -0.11259; 98.72735;1.00000
283.22299;   25.35000;    -0.11288; 98.71892;1.00000
283.72800;   25.40000;    -0.11343; 98.71892;1.00000
284.23599;   25.45000;    -0.11356; 98.70628;1.00000
284.72900;   25.50000;    -0.11423; 98.70628;1.00000
285.22199;   25.55000;    -0.11471; 98.69785;1.00000
285.72799;   25.60000;    -0.11491; 98.69785;1.00000
286.22800;   25.65000;    -0.11542; 98.69785;1.00000
286.73598;   25.70000;    -0.11555; 98.68942;1.00000
287.23801;   25.75000;    -0.11597; 98.68521;1.00000
287.72501;   25.80000;    -0.11600; 98.67678;1.00000
288.22400;   25.85000;    -0.11651; 98.67678;1.00000
288.73600;   25.90000;    -0.11703; 98.66835;1.00000
289.22601;   25.95000;    -0.11725; 98.66414;1.00000
289.71701;   26.00000;    -0.11770; 98.65992;1.00000
290.21799;   26.05000;    -0.11787; 98.65150;1.00000
290.71499;   26.10000;    -0.11812; 98.65150;1.00000
291.22800;   26.15000;    -0.11841; 98.64307;1.00000
291.73998;   26.20000;    -0.11870; 98.63885;1.00000
292.23300;   26.25000;    -0.11928; 98.63464;1.00000
292.72300;   26.30000;    -0.11960; 98.63042;1.00000
293.23599;   26.35000;    -0.11954; 98.62200;1.00000
293.72901;   26.40000;    -0.12008; 98.61778;1.00000
294.22799;   26.45000;    -0.11999; 98.61357;1.00000
294.71799;   26.50000;    -0.12028; 98.60936;1.00000
295.21799;   26.55000;    -0.12086; 98.60514;1.00000
295.72299;   26.60000;    -0.12082; 98.58828;1.00000
296.22501;   26.65000;    -0.12127; 98.57986;1.00000
296.71398;   26.70000;    -0.12166; 98.57986;1.00000
297.22400;   26.75000;    -0.12192; 98.57143;1.00000
297.72102;   26.80000;    -0.12185; 98.57143;1.00000
298.21600;   26.85000;    -0.12211; 98.57143;1.00000
298.72001;   26.90000;    -0.12237; 98.57143;1.00000
299.21301;   26.95000;    -0.12285; 98.56300;1.00000
299.71500;   27.00000;    -0.12291; 98.56300;1.00000
300.21900;   27.05000;    -0.12298; 98.55457;1.00000
300.71899;   27.10000;    -0.12320; 98.55036;1.00000
301.21601;   27.15000;    -0.12349; 98.55036;1.00000
301.70699;   27.20000;    -0.12385; 98.54614;1.00000
302.21399;   27.25000;    -0.12391; 98.53350;1.00000
302.71201;   27.30000;    -0.12413; 98.52929;1.00000
303.21099;   27.35000;    -0.12442; 98.52507;1.00000
303.72199;   27.40000;    -0.12462; 98.52086;1.00000
304.22198;   27.45000;    -0.12503; 98.51665;1.00000
304.72101;   27.50000;    -0.12503; 98.51243;1.00000
305.22901;   27.55000;    -0.12542; 98.50822;1.00000
305.71398;   27.60000;    -0.12558; 98.49136;1.00000
306.21000;   27.65000;    -0.12593; 98.49136;1.00000
306.72198;   27.70000;    -0.12584; 98.48293;1.00000
307.22699;   27.75000;    -0.12619; 98.47450;1.00000
307.71101;   27.80000;    -0.12616; 98.47451;1.00000
308.21701;   27.85000;    -0.12651; 98.46608;1.00000
308.71900;   27.90000;    -0.12671; 98.45765;1.00000
309.21300;   27.95000;    -0.12706; 98.45343;1.00000
309.71301;   28.00000;    -0.12722; 98.44079;1.00000
310.20499;   28.05000;    -0.12738; 98.43658;1.00000
310.70999;   28.10000;    -0.12757; 98.43236;1.00000
311.21100;   28.15000;    -0.12770; 98.42394;1.00000
311.70901;   28.20000;    -0.12793; 98.41972;1.00000
312.21100;   28.25000;    -0.12815; 98.41551;1.00000
312.70902;   28.30000;    -0.12838; 98.40708;1.00000
313.21701;   28.35000;    -0.12851; 98.39022;1.00000
313.70499;   28.40000;    -0.12854; 98.38180;1.00000
314.21301;   28.45000;    -0.12896; 98.37758;1.00000
314.70801;   28.50000;    -0.12915; 98.37337;1.00000
315.21900;   28.55000;    -0.12931; 98.36494;1.00000
315.71200;   28.60000;    -0.12960; 98.35230;1.00000
316.20401;   28.65000;    -0.12973; 98.34808;1.00000
316.71999;   28.70000;    -0.12983; 98.33965;1.00000
317.21899;   28.75000;    -0.13021; 98.33123;1.00000
317.71302;   28.80000;    -0.13024; 98.32280;1.00000
318.22198;   28.85000;    -0.13028; 98.31437;1.00000
318.73301;   28.90000;    -0.13021; 98.31016;1.00000
319.22799;   28.95000;    -0.13089; 98.29751;1.00000
319.72601;   29.00000;    -0.13108; 98.28909;1.00000
320.22300;   29.05000;    -0.13121; 98.28066;1.00000
320.72000;   29.10000;    -0.13153; 98.27223;1.00000
321.22199;   29.15000;    -0.13179; 98.25959;1.00000
321.70800;   29.20000;    -0.13188; 98.25116;1.00000
322.20801;   29.25000;    -0.13214; 98.24273;1.00000
322.71601;   29.30000;    -0.13249; 98.23852;1.00000
323.21301;   29.35000;    -0.13265; 98.23009;1.00000
323.72101;   29.40000;    -0.13282; 98.22587;1.00000
324.22100;   29.45000;    -0.13288; 98.22166;1.00000
324.71799;   29.50000;    -0.13307; 98.21323;1.00000
325.22102;   29.55000;    -0.13349; 98.20480;1.00000
325.72198;   29.60000;    -0.13368; 98.19216;1.00000
326.21201;   29.65000;    -0.13394; 98.18373;1.00000
326.71600;   29.70000;    -0.13429; 98.17531;1.00000
327.21701;   29.75000;    -0.13433; 98.16266;1.00000
327.71302;   29.80000;    -0.13407; 98.14581;1.00000
328.21701;   29.85000;    -0.13445; 98.13316;1.00000
328.72699;   29.90000;    -0.13484; 98.13316;1.00000
329.23098;   29.95000;    -0.13462; 98.12052;1.00000
329.72101;   30.00000;    -0.13523; 98.10788;1.00000
330.21500;   30.05000;    -0.13529; 98.09945;1.00000
330.71399;   30.10000;    -0.13526; 98.08681;1.00000
331.22501;   30.15000;    -0.13529; 98.07838;1.00000
331.72298;   30.20000;    -0.13577; 98.05731;1.00000
332.22400;   30.25000;    -0.13603; 98.04888;1.00000
332.72199;   30.30000;    -0.13629; 98.04045;1.00000
333.22198;   30.35000;    -0.13619; 98.02360;1.00000
333.71799;   30.40000;    -0.13613; 98.01096;1.00000
334.21999;   30.45000;    -0.13638; 98.00253;1.00000
334.72501;   30.50000;    -0.13661; 97.98989;1.00000
335.23200;   30.55000;    -0.13696; 97.98146;1.00000
335.71600;   30.60000;    -0.13716; 97.96882;1.00000
336.21900;   30.65000;    -0.13728; 97.95196;1.00000
336.71099;   30.70000;    -0.13741; 97.93932;1.00000
337.22699;   30.75000;    -0.13770; 97.93089;1.00000
337.72300;   30.80000;    -0.13770; 97.91403;1.00000
338.21899;   30.85000;    -0.13780; 97.89296;1.00000
338.71302;   30.90000;    -0.13812; 97.88032;1.00000
339.22198;   30.95000;    -0.13799; 97.86346;1.00000
339.72400;   31.00000;    -0.13825; 97.85082;1.00000
340.21601;   31.05000;    -0.13825; 97.82554;1.00000
340.71399;   31.10000;    -0.13863; 97.81290;1.00000
341.21900;   31.15000;    -0.13854; 97.79182;1.00000
341.71398;   31.20000;    -0.13851; 97.77918;1.00000
342.21100;   31.25000;    -0.13902; 97.76233;1.00000
342.70701;   31.30000;    -0.13915; 97.74547;1.00000
343.21499;   31.35000;    -0.13912; 97.72861;1.00000
343.71201;   31.40000;    -0.13905; 97.70333;1.00000
344.21099;   31.45000;    -0.13937; 97.69069;1.00000
344.70901;   31.50000;    -0.13928; 97.67383;1.00000
345.20701;   31.55000;    -0.13982; 97.64855;1.00000
345.71399;   31.60000;    -0.13957; 97.61905;1.00000
346.21399;   31.65000;    -0.13986; 97.60219;1.00000
346.70599;   31.70000;    -0.13992; 97.57691;1.00000
347.21100;   31.75000;    -0.14015; 97.55584;1.00000
347.71201;   31.80000;    -0.14063; 97.53055;1.00000
348.22299;   31.85000;    -0.14060; 97.50948;1.00000
348.71799;   31.90000;    -0.14053; 97.48420;1.00000
349.21398;   31.95000;    -0.14095; 97.45891;1.00000
349.71500;   32.00000;    -0.14085; 97.42520;1.00000
350.21400;   32.05000;    -0.14108; 97.39992;1.00000
350.71001;   32.10000;    -0.14143; 97.37042;1.00000
351.20299;   32.15000;    -0.14140; 97.34092;1.00000
351.71600;   32.20000;    -0.14150; 97.30299;1.00000
352.20999;   32.25000;    -0.14162; 97.26507;1.00000
352.71702;   32.30000;    -0.14172; 97.23557;1.00000
353.20402;   32.35000;    -0.14172; 97.18078;1.00000
353.70998;   32.40000;    -0.14179; 97.14707;1.00000
354.19399;   32.45000;    -0.14201; 97.10915;1.00000
354.71500;   32.50000;    -0.14185; 97.07543;1.00000
355.20200;   32.55000;    -0.14191; 97.04593;1.00000
355.70100;   32.60000;    -0.14162; 97.01222;1.00000
356.19197;   32.65000;    -0.14185; 96.97851;1.00000
356.69399;   32.70000;    -0.14201; 96.94058;1.00000
357.20099;   32.75000;    -0.14207; 96.90265;1.00000
357.69801;   32.80000;    -0.14204; 96.86051;1.00000
358.20500;   32.85000;    -0.14162; 96.81837;1.00000
358.69698;   32.90000;    -0.14156; 96.78045;1.00000
359.19698;   32.95000;    -0.14153; 96.74673;1.00000
359.69000;   33.00000;    -0.14117; 96.70038;1.00000
360.20200;   33.05000;    -0.14095; 96.66245;1.00000
360.69603;   33.10000;    -0.14043; 96.62452;1.00000
361.20000;   33.15000;    -0.14040; 96.57817;1.00000
361.69601;   33.20000;    -0.14005; 96.53182;1.00000
362.20999;   33.25000;    -0.13995; 96.48546;1.00000
362.71900;   33.30000;    -0.13950; 96.44753;1.00000
363.21001;   33.35000;    -0.13937; 96.39696;1.00000
363.71498;   33.40000;    -0.13896; 96.35061;1.00000
364.20599;   33.45000;    -0.13880; 96.29161;1.00000
364.71201;   33.50000;    -0.13847; 96.24526;1.00000
365.21900;   33.55000;    -0.13815; 96.19469;1.00000
365.70802;   33.60000;    -0.13789; 96.14412;1.00000
366.21998;   33.65000;    -0.13751; 96.08934;1.00000
366.71700;   33.70000;    -0.13716; 96.03877;1.00000
367.20599;   33.75000;    -0.13651; 95.96292;1.00000
367.71101;   33.80000;    -0.13622; 95.88706;1.00000
368.20500;   33.85000;    -0.13600; 95.81542;1.00000
368.71098;   33.90000;    -0.13526; 95.74800;1.00000
369.20901;   33.95000;    -0.13490; 95.68900;1.00000
369.70300;   34.00000;    -0.13462; 95.63422;1.00000
370.20801;   34.05000;    -0.13400; 95.58365;1.00000
370.70802;   34.10000;    -0.13343; 95.51201;1.00000
371.22099;   34.15000;    -0.13275; 95.42352;1.00000
371.69900;   34.20000;    -0.13204; 95.34766;1.00000
372.20499;   34.25000;    -0.13121; 95.26759;1.00000
372.71302;   34.30000;    -0.13063; 95.19595;1.00000
373.20802;   34.35000;    -0.12986; 95.13274;1.00000
373.71300;   34.40000;    -0.12899; 95.05689;1.00000
374.20599;   34.45000;    -0.12873; 94.96840;1.00000
374.70901;   34.50000;    -0.12783; 94.88833;1.00000
375.19801;   34.55000;    -0.12725; 94.79562;1.00000
375.70500;   34.60000;    -0.12674; 94.71555;1.00000
376.20900;   34.65000;    -0.12590; 94.63127;1.00000
376.70699;   34.70000;    -0.12552; 94.54277;1.00000
377.20700;   34.75000;    -0.12446; 94.44585;1.00000
377.70002;   34.80000;    -0.12401; 94.34892;1.00000
378.20302;   34.85000;    -0.12288; 94.25621;1.00000
378.70598;   34.90000;    -0.12159; 94.15087;1.00000
379.20800;   34.95000;    -0.12008; 94.04130;1.00000
379.70200;   35.00000;    -0.11867; 93.93595;1.00000
380.21000;   35.05000;    -0.11735; 93.82216;1.00000
380.69603;   35.10000;    -0.11642; 93.70838;1.00000
381.20000;   35.15000;    -0.11542; 93.59040;1.00000
381.69900;   35.20000;    -0.11439; 93.46819;1.00000
382.19901;   35.25000;    -0.11330; 93.33333;1.00000
382.71101;   35.30000;    -0.11211; 93.20691;1.00000
383.20100;   35.35000;    -0.11095; 93.07206;1.00000
383.70497;   35.40000;    -0.11008; 92.94143;1.00000
384.20699;   35.45000;    -0.10883; 92.80236;1.00000
384.70901;   35.50000;    -0.10761; 92.65908;1.00000
385.20301;   35.55000;    -0.10607; 92.52001;1.00000
385.70601;   35.60000;    -0.10465; 92.37673;1.00000
386.20399;   35.65000;    -0.10320; 92.22082;1.00000
386.69900;   35.70000;    -0.10218; 92.06490;1.00000
387.20901;   35.75000;    -0.10063; 91.90476;1.00000
387.69901;   35.80000;-9.8800e-002; 91.74041;1.00000
388.20403;   35.85000;-9.7417e-002; 91.57184;1.00000
388.69798;   35.90000;-9.6003e-002; 91.40329;1.00000
389.21398;   35.95000;-9.4298e-002; 91.22630;1.00000
389.70801;   36.00000;-9.2498e-002; 91.04088;1.00000
390.19501;   36.05000;-9.0794e-002; 90.85967;1.00000
390.71001;   36.10000;-8.8833e-002; 90.67425;1.00000
391.19899;   36.15000;-8.7225e-002; 90.48463;1.00000
391.70400;   36.20000;-8.5232e-002; 90.29077;1.00000
392.19501;   36.25000;-8.3624e-002; 90.09271;1.00000
392.70200;   36.30000;-8.1406e-002; 89.89886;1.00000
393.21001;   36.35000;-7.9477e-002; 89.68815;1.00000
393.69899;   36.40000;-7.7548e-002; 89.47325;1.00000
394.20000;   36.45000;-7.5747e-002; 89.25833;1.00000
394.70599;   36.50000;-7.3690e-002; 89.03919;1.00000
395.20002;   36.55000;-7.1696e-002; 88.81163;1.00000
395.70701;   36.60000;-6.9060e-002; 88.57985;1.00000
396.20399;   36.65000;-6.7452e-002; 88.34388;1.00000
396.70901;   36.70000;-6.5170e-002; 88.11210;1.00000
397.20599;   36.75000;-6.2919e-002; 87.86346;1.00000
397.71201;   36.80000;-6.0218e-002; 87.58955;1.00000
398.21703;   36.85000;-5.8579e-002; 87.33670;1.00000
398.71999;   36.90000;-5.6135e-002; 87.07965;1.00000
399.20998;   36.95000;-5.3467e-002; 86.82259;1.00000
399.71100;   37.00000;-5.1441e-002; 86.55289;1.00000
400.22101;   37.05000;-4.8966e-002; 86.27475;1.00000
400.71101;   37.10000;-4.6651e-002; 86.00083;1.00000
401.21599;   37.15000;-4.4497e-002; 85.72272;1.00000
401.71200;   37.20000;-4.2375e-002; 85.42773;1.00000
402.21799;   37.25000;-3.9803e-002; 85.12853;1.00000
402.71601;   37.30000;-3.7327e-002; 84.83354;1.00000
403.22002;   37.35000;-3.5559e-002; 84.53855;1.00000
403.72798;   37.40000;-3.2987e-002; 84.21830;1.00000
404.21200;   37.45000;-3.0801e-002; 83.90224;1.00000
404.71600;   37.50000;-2.8550e-002; 83.58196;1.00000
405.20902;   37.55000;-2.5881e-002; 83.25748;1.00000
405.72301;   37.60000;-2.3920e-002; 82.92877;1.00000
406.21699;   37.65000;-2.2056e-002; 82.59167;1.00000
406.71499;   37.70000;-2.0126e-002; 82.24611;1.00000
407.22400;   37.75000;-1.8133e-002; 81.90476;1.00000
407.71500;   37.80000;-1.5625e-002; 81.54235;1.00000
408.22102;   37.85000;-1.3343e-002; 81.17993;1.00000
408.71797;   37.90000;-1.1542e-002; 80.81754;1.00000
409.22100;   37.95000;-8.9701e-003; 80.45091;1.00000
409.71899;   38.00000;-7.2339e-003; 80.07164;1.00000
410.22102;   38.05000;-4.9833e-003; 79.69237;1.00000
410.72902;   38.10000;-3.4080e-003; 79.30888;1.00000
411.23598;   38.15000;-2.4113e-003; 78.92121;1.00000
411.72900;   38.20000;-1.9612e-003; 78.52929;1.00000
412.22299;   38.25000;-1.8647e-003; 78.13738;1.00000
412.71900;   38.30000;-1.5111e-003; 77.70754;1.00000
413.22200;   38.35000;-1.9933e-003; 77.31141;1.00000
413.71700;   38.40000;-1.7040e-003; 76.91110;1.00000
414.22198;   38.45000;-1.7040e-003; 76.50654;1.00000
414.71399;   38.50000;-2.0898e-003; 76.09355;1.00000
415.21500;   38.55000;-2.5399e-003; 75.68057;1.00000
415.72200;   38.60000;-3.2151e-003; 75.27180;1.00000
416.21700;   38.65000;-3.6330e-003; 74.85463;1.00000
416.71099;   38.70000;-4.6940e-003; 74.44164;1.00000
417.21301;   38.75000;-5.8193e-003; 74.02444;1.00000
417.71900;   38.80000;-7.1697e-003; 73.60724;1.00000
418.19701;   38.85000;-9.1309e-003; 73.17740;1.00000
418.70097;   38.90000;-1.0706e-002; 72.76023;1.00000
419.19100;   38.95000;-1.2378e-002; 72.34303;1.00000
419.69901;   39.00000;-1.4564e-002; 71.93426;1.00000
420.20499;   39.05000;-1.6654e-002; 71.52127;1.00000
420.69902;   39.10000;-1.8648e-002; 71.10408;1.00000
421.19798;   39.15000;-2.0898e-002; 70.69112;1.00000
421.70300;   39.20000;-2.2891e-002; 70.28235;1.00000
422.20001;   39.25000;-2.5463e-002; 69.86515;1.00000
422.71000;   39.30000;-2.7778e-002; 69.45638;1.00000
423.20601;   39.35000;-3.0350e-002; 69.04761;1.00000
423.71300;   39.40000;-3.2954e-002; 68.65151;1.00000
424.20098;   39.45000;-3.5237e-002; 68.24274;1.00000
424.70300;   39.50000;-3.8227e-002; 67.83818;1.00000
425.21302;   39.55000;-4.1121e-002; 67.43784;1.00000
425.70403;   39.60000;-4.3918e-002; 67.04171;1.00000
426.21599;   39.65000;-4.6844e-002; 66.64139;1.00000
426.72198;   39.70000;-5.0027e-002; 66.24105;1.00000
427.22101;   39.75000;-5.3242e-002; 65.84492;1.00000
427.71601;   39.80000;-5.5975e-002; 65.41929;1.00000
428.22301;   39.85000;-5.9769e-002; 65.03581;1.00000
428.71898;   39.90000;-6.2983e-002; 64.64392;1.00000
429.21499;   39.95000;-6.6552e-002; 64.25622;1.00000
429.71600;   40.00000;-7.0571e-002; 63.87274;1.00000
430.22199;   40.05000;-7.3561e-002; 63.49767;1.00000
430.71602;   40.10000;-7.7001e-002; 63.11419;1.00000
431.23198;   40.15000;-8.0248e-002; 62.73495;1.00000
431.72500;   40.20000;-8.3785e-002; 62.36410;1.00000
432.22900;   40.25000;-8.7643e-002; 61.98904;1.00000
432.72401;   40.30000;-9.0698e-002; 61.60977;1.00000
433.23601;   40.35000;-9.4749e-002; 61.24314;1.00000
433.72697;   40.40000;-9.8060e-002; 60.87654;1.00000
434.22698;   40.45000;    -0.10182; 60.52255;1.00000
434.72400;   40.50000;    -0.10481; 60.15592;1.00000
435.22300;   40.55000;    -0.10870; 59.80193;1.00000
435.72902;   40.60000;    -0.11192; 59.45216;1.00000
436.22398;   40.65000;    -0.11584; 59.11505;1.00000
436.73901;   40.70000;    -0.11902; 58.76950;1.00000
437.23599;   40.75000;    -0.12214; 58.42815;1.00000
437.72102;   40.80000;    -0.12529; 58.09102;1.00000
438.22801;   40.85000;    -0.12880; 57.76231;1.00000
438.73497;   40.90000;    -0.13156; 57.42521;1.00000
439.23998;   40.95000;    -0.13474; 57.09229;1.00000
439.73999;   41.00000;    -0.13764; 56.75938;1.00000
440.23499;   41.05000;    -0.14050; 56.43489;1.00000
440.71901;   41.10000;    -0.14307; 56.10618;1.00000
441.22499;   41.15000;    -0.14625; 55.77329;1.00000
441.73000;   41.20000;    -0.14850; 55.44880;1.00000
442.23199;   41.25000;    -0.15082; 55.13275;1.00000
442.72001;   41.30000;    -0.15375; 54.80825;1.00000
443.24800;   41.35000;    -0.15616; 54.46270;1.00000
443.73399;   41.40000;    -0.15837; 54.13823;1.00000
444.22399;   41.45000;    -0.16095; 53.81374;1.00000
444.72601;   41.50000;    -0.16310; 53.48925;1.00000
445.22300;   41.55000;    -0.16526; 53.16055;1.00000
445.72603;   41.60000;    -0.16725; 52.84028;1.00000
446.23598;   41.65000;    -0.16985; 52.51581;1.00000
446.73000;   41.70000;    -0.17204; 52.19975;1.00000
447.23300;   41.75000;    -0.17390; 51.87948;1.00000
447.73499;   41.80000;    -0.17612; 51.55499;1.00000
448.22603;   41.85000;    -0.17812; 51.23893;1.00000
448.71797;   41.90000;    -0.18030; 50.92289;1.00000
449.22298;   41.95000;    -0.18204; 50.60262;1.00000
449.73199;   42.00000;    -0.18416; 50.27813;1.00000
450.22501;   42.05000;    -0.18635; 49.97050;1.00000
450.72701;   42.10000;    -0.18815; 49.65865;1.00000
451.23497;   42.15000;    -0.18988; 49.33419;1.00000
451.73498;   42.20000;    -0.19159; 49.02234;1.00000
452.23401;   42.25000;    -0.19352; 48.71471;1.00000
452.73801;   42.30000;    -0.19561; 48.40707;1.00000
453.23903;   42.35000;    -0.19721; 48.09944;1.00000
453.73198;   42.40000;    -0.19908; 47.79183;1.00000
454.22601;   42.45000;    -0.20081; 47.49263;1.00000
454.72699;   42.50000;    -0.20284; 47.19342;1.00000
455.23002;   42.55000;    -0.20438; 46.89422;1.00000
455.73100;   42.60000;    -0.20625; 46.59923;1.00000
456.23799;   42.65000;    -0.20814; 46.31269;1.00000
456.74300;   42.70000;    -0.20966; 46.03034;1.00000
457.23401;   42.75000;    -0.21126; 45.73536;1.00000
457.72901;   42.80000;    -0.21300; 45.45301;1.00000
458.23903;   42.85000;    -0.21467; 45.15380;1.00000
458.73997;   42.90000;    -0.21654; 44.86726;1.00000
459.24398;   42.95000;    -0.21818; 44.58910;1.00000
459.73300;   43.00000;    -0.21991; 44.17615;1.00000
460.22602;   43.05000;    -0.22178; 43.89802;1.00000
460.73802;   43.10000;    -0.22322; 43.76317;1.00000
461.22798;   43.15000;    -0.22470; 43.52719;1.00000
461.72799;   43.20000;    -0.22666; 43.27013;1.00000
462.22800;   43.25000;    -0.22782; 43.02992;1.00000
462.72901;   43.30000;    -0.22965; 42.78128;1.00000
463.22902;   43.35000;    -0.23071; 42.52001;1.00000
463.72798;   43.40000;    -0.23229; 42.28825;1.00000
464.22500;   43.45000;    -0.23399; 42.05226;1.00000
464.72299;   43.50000;    -0.23541; 41.82470;1.00000
465.22001;   43.55000;    -0.23673; 41.60134;1.00000
465.72701;   43.60000;    -0.23824; 41.36957;1.00000
466.22499;   43.65000;    -0.23965; 41.15888;1.00000
466.73400;   43.70000;    -0.24120; 40.95239;1.00000
467.21899;   43.75000;    -0.24226; 40.75011;1.00000
467.72700;   43.80000;    -0.24361; 40.54361;1.00000
468.22200;   43.85000;    -0.24483; 40.34555;1.00000
468.72099;   43.90000;    -0.24570; 40.16014;1.00000
469.21899;   43.95000;    -0.24708; 39.96629;1.00000
469.72400;   44.00000;    -0.24849; 39.78087;1.00000
470.22501;   44.05000;    -0.24962; 39.59545;1.00000
470.72502;   44.10000;    -0.25081; 39.42267;1.00000
471.22899;   44.15000;    -0.25206; 39.24990;1.00000
471.71499;   44.20000;    -0.25290; 39.08133;1.00000
472.21399;   44.25000;    -0.25425; 38.92541;1.00000
472.72001;   44.30000;    -0.25528; 38.76949;1.00000
473.21703;   44.35000;    -0.25624; 38.61778;1.00000
473.71898;   44.40000;    -0.25740; 38.46187;1.00000
474.22100;   44.45000;    -0.25840; 38.31437;1.00000
474.73199;   44.50000;    -0.25952; 38.17109;1.00000
475.22901;   44.55000;    -0.26039; 38.03624;1.00000
475.71703;   44.60000;    -0.26135; 37.90560;1.00000
476.21700;   44.65000;    -0.26274; 37.78340;1.00000
476.72399;   44.70000;    -0.26335; 37.66540;1.00000
477.23999;   44.75000;    -0.26415; 37.53477;1.00000
477.73902;   44.80000;    -0.26531; 37.42520;1.00000
478.23003;   44.85000;    -0.26647; 37.31563;1.00000
478.72499;   44.90000;    -0.26733; 37.20607;1.00000
479.22198;   44.95000;    -0.26833; 37.10493;1.00000
479.72800;   45.00000;    -0.26926; 37.00801;1.00000
480.23200;   45.05000;    -0.26994; 36.91108;1.00000
480.72200;   45.10000;    -0.27126; 36.81416;1.00000
481.22197;   45.15000;    -0.27203; 36.72145;1.00000
481.73699;   45.20000;    -0.27341; 36.64560;1.00000
482.22501;   45.25000;    -0.27418; 36.56553;1.00000
482.71900;   45.30000;    -0.27495; 36.49389;1.00000
483.23903;   45.35000;    -0.27624; 36.42646;1.00000
483.71998;   45.40000;    -0.27682; 36.33797;1.00000
484.22298;   45.45000;    -0.27782; 36.26633;1.00000
484.72501;   45.50000;    -0.27875; 36.20733;1.00000
485.22800;   45.55000;    -0.27946; 36.15676;1.00000
485.72603;   45.60000;    -0.28016; 36.10619;1.00000
486.21398;   45.65000;    -0.28109; 36.05984;1.00000
486.72198;   45.70000;    -0.28222; 36.00506;1.00000
487.21600;   45.75000;    -0.28296; 35.95870;1.00000
487.72102;   45.80000;    -0.28338; 35.89549;1.00000
488.22200;   45.85000;    -0.28447; 35.84914;1.00000
488.71098;   45.90000;    -0.28544; 35.79436;1.00000
489.21600;   45.95000;    -0.28662; 35.74800;1.00000
489.71201;   46.00000;    -0.28727; 35.71428;1.00000
490.21900;   46.05000;    -0.28798; 35.67636;1.00000
490.70903;   46.10000;    -0.28855; 35.64686;1.00000
491.21599;   46.15000;    -0.28923; 35.61315;1.00000
491.70800;   46.20000;    -0.29016; 35.58365;1.00000
492.21201;   46.25000;    -0.29061; 35.55415;1.00000
492.70701;   46.30000;    -0.29093; 35.52886;1.00000
493.20601;   46.35000;    -0.29183; 35.50780;1.00000
493.71098;   46.40000;    -0.29199; 35.48673;1.00000
494.21499;   46.45000;    -0.29293; 35.46987;1.00000
494.71600;   46.50000;    -0.29392; 35.44880;1.00000
495.21201;   46.55000;    -0.29428; 35.42773;1.00000
495.71101;   46.60000;    -0.29505; 35.41509;1.00000
496.21300;   46.65000;    -0.29537; 35.39402;1.00000
496.70998;   46.70000;    -0.29569; 35.37295;1.00000
497.20801;   46.75000;    -0.29614; 35.35609;1.00000
497.70802;   46.80000;    -0.29688; 35.34345;1.00000
498.21501;   46.85000;    -0.29707; 35.32659;1.00000
498.71999;   46.90000;    -0.29730; 35.30973;1.00000
499.21600;   46.95000;    -0.29778; 35.29709;1.00000
499.61299;   46.99000;    -0.29797; 35.28866;1.00000